<?xml version="1.0"?>
<robot name="Rodney">

  <!-- The mass values need checking and then the moments of inertia changing for any mass changes --> 
  
  <material name="blue">
    <color rgba="0 0 0.8 1"/>
  </material>
  
  <material name="white">
    <color rgba="1 1 1 1"/>
  </material>
  
  <material name="black">
    <color rgba="0 0 0 1"/>
  </material>  
  
  <material name="silver">
    <color rgba="0.75 0.75 0.75 1"/>
  </material>   
  
  <material name="bronze">
    <color rgba="0.8 0.498 0.196 1"/>
  </material>  
  
  <link name="base_link">
    <visual>      
      <geometry>        
        <mesh filename="package://rodney/meshes/rodneyBase.dae"/>        
      </geometry>      
    </visual>
    <collision>
      <geometry>
        <box size="0.340 0.180 0.008"/>
      </geometry>
      <origin xyz="0.0 0.0 0.004"/>
    </collision>
    <inertial>
      <mass value="2"/>
      <inertia ixx="0.005411" ixy="0.0" ixz="0.0" iyy="0.024667" iyz="0.0" izz="0.019277"/>      
    </inertial>
  </link>
  
  <!-- Motors and wheels -->
  
  <!-- Front left -->

  <link name="front_left_motor_bracket">
    <visual>
      <geometry>
        <box size="0.042 0.049 0.002"/>
      </geometry>      
      <origin rpy="1.58 0 0" xyz="0.0 0.0 -0.0245"/>
      <material name="bronze"/>
    </visual>
    <collision>
      <geometry>
        <box size="0.042 0.049 0.002"/>
      </geometry>
      <origin rpy="1.58 0 0" xyz="0.0 0.0 -0.0245"/>
    </collision>
    <inertial>
      <mass value="0.035"/>
      <inertia ixx="7.01e-6" ixy="0.0" ixz="0.0" iyy="1.21e-5" iyz="0.0" izz="5.16e-6"/>
    </inertial>    
  </link>

  <joint name="base_to_fl_motor_brk" type="fixed">
    <parent link="base_link"/>
    <child link="front_left_motor_bracket"/>
    <origin xyz="0.075 0.091 0.0"/>
  </joint>
        
  <link name="front_left_motor">
    <visual>
      <geometry>
        <cylinder length="0.056" radius="0.0185"/>
      </geometry>
      <origin rpy="1.57 0 0" xyz="0.0 -0.028 0.0"/>
      <material name="silver"/>
    </visual>
    <collision>
      <geometry>
        <cylinder length="0.056" radius="0.0185"/>
      </geometry>
      <origin rpy="1.57 0 0" xyz="0.0 -0.028 0.0"/>
    </collision>
    <inertial>
      <mass value="0.198"/>
      <inertia ixx="6.86854e-5" ixy="0.0" ixz="0.0" iyy="6.86854e-5" iyz="0.0" izz="3.38828e-5"/>
    </inertial>               
  </link>
  
  <joint name="fl_brk_to_fl_motor" type="fixed">
    <parent link="front_left_motor_bracket"/>
    <child link="front_left_motor"/>    
    <origin xyz="0.0 -0.001 -0.028"/>
  </joint>
 
  <link name="front_left_wheel">
    <visual>
      <geometry>
        <cylinder length="0.050" radius="0.053"/>
      </geometry>
      <origin rpy="1.57 0 0" xyz="0.0 0.025 0.0"/>      
      <material name="black"/>
    </visual>
    <collision>
      <geometry>
        <cylinder length="0.050" radius="0.053"/>
      </geometry>
      <origin rpy="1.57 0 0" xyz="0.0 0.025 0.0"/>     
    </collision>
    <inertial>
      <mass value="0.105"/>
      <inertia ixx="9.56113e-5" ixy="0.0" ixz="0.0" iyy="9.56113e-5" iyz="0.0" izz="0.000147473"/>
    </inertial>   
  </link>
  
  <joint name="fl_brk_to_wheel" type="continuous">
    <axis xyz="0 1 0"/>
    <parent link="front_left_motor_bracket"/>
    <child link="front_left_wheel"/>
    <origin xyz="0.0 0.001 -0.034"/>
  </joint>
  
  <!-- Front right -->
  
  <link name="front_right_motor_bracket">
    <visual>
      <geometry>
        <box size="0.042 0.049 0.002"/>
      </geometry>
      <origin rpy="1.58 0 0" xyz="0.0 0.0 -0.0245"/>      
      <material name="bronze"/>
    </visual>
    <collision>
      <geometry>
        <box size="0.042 0.049 0.002"/>
      </geometry>
      <origin rpy="1.58 0 0" xyz="0.0 0.0 -0.0245"/>
    </collision>
    <inertial>
      <mass value="0.035"/>
      <inertia ixx="7.01e-6" ixy="0.0" ixz="0.0" iyy="1.21e-5" iyz="0.0" izz="5.16e-6"/>
    </inertial>     
  </link>

  <joint name="base_to_fr_motor_brk" type="fixed">
    <parent link="base_link"/>
    <child link="front_right_motor_bracket"/>
    <origin xyz="0.075 -0.091 0.0"/>
  </joint>
           
  <link name="front_right_motor">
    <visual>
      <geometry>
        <cylinder length="0.056" radius="0.0185"/>
      </geometry>
      <origin rpy="1.57 0 0" xyz="0.0 0.028 0.0"/>      
      <material name="silver"/>
    </visual>
    <collision>
      <geometry>
        <cylinder length="0.056" radius="0.0185"/>
      </geometry>
      <origin rpy="1.57 0 0" xyz="0.0 0.028 0.0"/>
    </collision>
    <inertial>
      <mass value="0.198"/>
      <inertia ixx="6.86854e-5" ixy="0.0" ixz="0.0" iyy="6.86854e-5" iyz="0.0" izz="3.38828e-5"/>
    </inertial>     
  </link>
  
  <joint name="fr_brk_to_fr_motor" type="fixed">
    <parent link="front_right_motor_bracket"/>
    <child link="front_right_motor"/>    
    <origin xyz="0.0 0.001 -0.028"/>
  </joint>
   
  <link name="front_right_wheel">
    <visual>
      <geometry>
        <cylinder length="0.050" radius="0.053"/>
      </geometry>
      <origin rpy="1.57 0 0" xyz="0.0 -0.025 0.0"/>      
      <material name="black"/>
    </visual>
    <collision>
      <geometry>
        <cylinder length="0.050" radius="0.053"/>
      </geometry>
      <origin rpy="1.57 0 0" xyz="0.0 -0.025 0.0"/>     
    </collision>
    <inertial>
      <mass value="0.105"/>
      <inertia ixx="9.56113e-5" ixy="0.0" ixz="0.0" iyy="9.56113e-5" iyz="0.0" izz="0.000147473"/>
    </inertial>    
  </link>
  
  <joint name="fr_brk_to_wheel" type="continuous">
    <axis xyz="0 1 0"/>
    <parent link="front_right_motor_bracket"/>
    <child link="front_right_wheel"/>
    <origin xyz="0.0 -0.001 -0.034"/>
  </joint>

  <!-- Rear left -->
 
  <link name="rear_left_motor_bracket">
    <visual>
      <geometry>
        <box size="0.042 0.049 0.002"/>
      </geometry>
      <origin rpy="1.58 0 0" xyz="0.0 0.0 -0.0245"/>      
      <material name="bronze"/>
    </visual>
    <collision>
      <geometry>
        <box size="0.042 0.049 0.002"/>
      </geometry>
      <origin rpy="1.58 0 0" xyz="0.0 0.0 -0.0245"/>
    </collision>
    <inertial>
      <mass value="0.035"/>
      <inertia ixx="7.01e-6" ixy="0.0" ixz="0.0" iyy="1.21e-5" iyz="0.0" izz="5.16e-6"/>
    </inertial>     
  </link>

  <joint name="base_to_rl_motor_brk" type="fixed">
    <parent link="base_link"/>
    <child link="rear_left_motor_bracket"/>    
    <origin xyz="-0.075 0.091 0.0"/>
  </joint>
       
  <link name="rear_left_motor">
    <visual>
      <geometry>
        <cylinder length="0.056" radius="0.0185"/>
      </geometry>
      <origin rpy="1.57 0 0" xyz="0.0 -0.028 0.0"/>      
      <material name="silver"/>
    </visual>
    <collision>
      <geometry>
        <cylinder length="0.056" radius="0.0185"/>
      </geometry>
      <origin rpy="1.57 0 0" xyz="0.0 -0.028 0.0"/>
    </collision>
    <inertial>
      <mass value="0.198"/>
      <inertia ixx="6.86854e-5" ixy="0.0" ixz="0.0" iyy="6.86854e-5" iyz="0.0" izz="3.38828e-5"/>
    </inertial>     
  </link>
  
  <joint name="rl_brk_to_rl_motor" type="fixed">
    <parent link="rear_left_motor_bracket"/>
    <child link="rear_left_motor"/>
    <origin xyz="0.0 -0.001 -0.028"/>
  </joint>
   
  <link name="rear_left_wheel">
    <visual>
      <geometry>
        <cylinder length="0.050" radius="0.053"/>
      </geometry>
      <origin rpy="1.57 0 0" xyz="0.0 0.025 0.0"/>      
      <material name="black"/>
    </visual>
    <collision>
      <geometry>
        <cylinder length="0.050" radius="0.053"/>
      </geometry>
      <origin rpy="1.57 0 0" xyz="0.0 0.025 0.0"/>     
    </collision>
    <inertial>
      <mass value="0.105"/>
      <inertia ixx="9.56113e-5" ixy="0.0" ixz="0.0" iyy="9.56113e-5" iyz="0.0" izz="0.000147473"/>
    </inertial>    
  </link>
  
  <joint name="rl_brk_to_wheel" type="continuous">
    <axis xyz="0 1 0"/>
    <parent link="rear_left_motor_bracket"/>
    <child link="rear_left_wheel"/>
    <origin xyz="0.0 0.001 -0.034"/>
  </joint>

  <!-- Rear right -->
  
  <link name="rear_right_motor_bracket">
    <visual>
      <geometry>
        <box size="0.042 0.049 0.002"/>
      </geometry>
      <origin rpy="1.58 0 0" xyz="0.0 0.0 -0.0245"/>      
      <material name="bronze"/>
    </visual>
    <collision>
      <geometry>
        <box size="0.042 0.049 0.002"/>
      </geometry>
      <origin rpy="1.58 0 0" xyz="0.0 0.0 -0.0245"/>
    </collision>
    <inertial>
      <mass value="0.035"/>
      <inertia ixx="7.01e-6" ixy="0.0" ixz="0.0" iyy="1.21e-5" iyz="0.0" izz="5.16e-6"/>
    </inertial> 
  </link>

  <joint name="base_to_rr_motor_brk" type="fixed">
    <parent link="base_link"/>
    <child link="rear_right_motor_bracket"/>
    <origin xyz="-0.075 -0.091 0.0"/>
  </joint>
        
  <link name="rear_right_motor">
    <visual>
      <geometry>
        <cylinder length="0.056" radius="0.0185"/>
      </geometry>
      <origin rpy="1.57 0 0" xyz="0.0 0.028 0.0"/>      
      <material name="silver"/>
    </visual>
    <collision>
      <geometry>
        <cylinder length="0.056" radius="0.0185"/>
      </geometry>
      <origin rpy="1.57 0 0" xyz="0.0 0.028 0.0"/>
    </collision>
    <inertial>
      <mass value="0.198"/>
      <inertia ixx="6.86854e-5" ixy="0.0" ixz="0.0" iyy="6.86854e-5" iyz="0.0" izz="3.38828e-5"/>
    </inertial>     
  </link>
  
  <joint name="rr_brk_to_rr_motor" type="fixed">
    <parent link="rear_right_motor_bracket"/>
    <child link="rear_right_motor"/>
    <origin xyz="0.0 0.001 -0.028"/>
  </joint>
  
  <link name="rear_right_wheel">
    <visual>
      <geometry>
        <cylinder length="0.050" radius="0.053"/>
      </geometry>
      <origin rpy="1.57 0 0" xyz="0.0 -0.025 0.0"/>      
      <material name="black"/>
    </visual>
    <collision>
      <geometry>
        <cylinder length="0.050" radius="0.053"/>
      </geometry>
      <origin rpy="1.57 0 0" xyz="0.0 -0.025 0.0"/>     
    </collision>
    <inertial>
      <mass value="0.105"/>
      <inertia ixx="9.56113e-5" ixy="0.0" ixz="0.0" iyy="9.56113e-5" iyz="0.0" izz="0.000147473"/>
    </inertial>    
  </link>
  
  <joint name="rr_brk_to_wheel" type="continuous">
    <axis xyz="0 1 0"/>
    <parent link="rear_right_motor_bracket"/>
    <child link="rear_right_wheel"/>
    <origin xyz="0.0 -0.001 -0.028"/>
  </joint>
       
  <!-- Rear platform -->
  
  <link name="post_1">
    <visual>
      <geometry>
        <cylinder length="0.05" radius="0.005"/>
      </geometry>
      <origin xyz="0.0 0.0 0.025"/>      
      <material name="blue"/>
    </visual>
    <collision>
      <geometry>
        <cylinder length="0.05" radius="0.005"/>
      </geometry>
      <origin xyz="0.0 0.0 0.025"/> 
    </collision>
    <inertial>
      <mass value="0.009"/>
      <inertia ixx="1.93125e-6" ixy="0.0" ixz="0.0" iyy="1.93125e-6" iyz="0.0" izz="1.125e-7"/>
    </inertial>           
  </link>
  
  <joint name="base_to_post_1" type="fixed">
    <parent link="base_link"/>
    <child link="post_1"/>
    <origin xyz="-0.06 0.08 0.008"/>
  </joint>
 
  <link name="post_2">
    <visual>
      <geometry>
        <cylinder length="0.05" radius="0.005"/>
      </geometry>
      <origin xyz="0.0 0.0 0.025"/>      
      <material name="blue"/>
    </visual>
    <collision>
      <geometry>
        <cylinder length="0.05" radius="0.005"/>
      </geometry>
      <origin xyz="0.0 0.0 0.025"/> 
    </collision>
    <inertial>
      <mass value="0.009"/>
      <inertia ixx="1.93125e-6" ixy="0.0" ixz="0.0" iyy="1.93125e-6" iyz="0.0" izz="1.125e-7"/>
    </inertial>    
  </link>
  
  <joint name="base_to_post_2" type="fixed">
    <parent link="base_link"/>
    <child link="post_2"/>
    <origin xyz="-0.14 0.08 0.008"/>
  </joint>
  
  <link name="post_3">
    <visual>
      <geometry>
        <cylinder length="0.05" radius="0.005"/>
      </geometry>
      <origin xyz="0.0 0.0 0.025"/>      
      <material name="blue"/>
    </visual>
    <collision>
      <geometry>
        <cylinder length="0.05" radius="0.005"/>
      </geometry>
      <origin xyz="0.0 0.0 0.025"/> 
    </collision>
    <inertial>
      <mass value="0.009"/>
      <inertia ixx="1.93125e-6" ixy="0.0" ixz="0.0" iyy="1.93125e-6" iyz="0.0" izz="1.125e-7"/>
    </inertial>    
  </link>
  
  <joint name="base_to_post_3" type="fixed">
    <parent link="base_link"/>
    <child link="post_3"/>
    <origin xyz="-0.06 -0.08 0.008"/>
  </joint>    
 
  <link name="post_4">
    <visual>
      <geometry>
        <cylinder length="0.05" radius="0.005"/>
      </geometry>
      <origin xyz="0.0 0.0 0.025"/>      
      <material name="blue"/>
    </visual>
    <collision>
      <geometry>
        <cylinder length="0.05" radius="0.005"/>
      </geometry>
      <origin xyz="0.0 0.0 0.025"/> 
    </collision>
    <inertial>
      <mass value="0.009"/>
      <inertia ixx="1.93125e-6" ixy="0.0" ixz="0.0" iyy="1.93125e-6" iyz="0.0" izz="1.125e-7"/>
    </inertial>    
  </link>
  
  <joint name="base_to_post_4" type="fixed">
    <parent link="base_link"/>
    <child link="post_4"/>
    <origin xyz="-0.14 -0.08 0.008"/>
  </joint>

  <link name="rear_platform">
    <visual>      
      <geometry>        
        <mesh filename="package://rodney/meshes/smallRearPlatform.dae"/>
      </geometry>
      <origin rpy="0 0 1.57" xyz="0.010 -0.080 0.0"/>              
    </visual>
    <collision>      
      <geometry>        
        <box size="0.180 0.098 0.003"/>
      </geometry>
      <origin rpy="0 0 1.57" xyz="-0.04 -0.080 0.0015"/>              
    </collision> 
    <inertial>
      <mass value="0.061"/>
      <inertia ixx="4.89e-5" ixy="0.0" ixz="0.0" iyy="0.000214" iyz="0.0" izz="0.000165"/>
    </inertial>        
  </link>  

  <joint name="post_1_to_rear_platform" type="fixed">
    <parent link="post_1"/>
    <child link="rear_platform"/>
    <origin xyz="0.0 0.0 0.05"/>
  </joint>

  <!-- Neck and head -->
   
  <link name="neck">
    <visual>
      <geometry>
        <cylinder length="0.30" radius="0.011"/>
      </geometry>
      <origin xyz="0 0.0 0.15"/>      
      <material name="white"/>
    </visual>
    <collision>
      <geometry>
        <cylinder length="0.30" radius="0.011"/>
      </geometry>
      <origin xyz="0 0.0 0.15"/>            
    </collision>
    <inertial>
      <mass value="0.030"/>
      <inertia ixx="0.000225908" ixy="0.0" ixz="0.0" iyy="0.000225908" iyz="0.0" izz="0.000001815"/>
    </inertial>         
  </link>
  
  <joint name="rear_platform_to_neck" type="fixed">
    <parent link="rear_platform"/>
    <child link="neck"/>
    <origin xyz="-0.070 -0.080 -0.050"/>
  </joint>  
  
  <link name="head_fixing">
    <visual>      
      <geometry>        
        <mesh filename="package://rodney/meshes/headFixing.dae"/>
      </geometry>
      <origin xyz="0.0 0.0 -0.040"/>            
    </visual>
    <collision>
      <geometry>        
        <box size="0.03 0.04 0.1"/>
      </geometry>
      <origin xyz="0.0 0.0 0.010"/> 
    </collision>
    <inertial>
      <mass value="0.015"/>
      <inertia ixx="1.48e-5" ixy="0.0" ixz="0.0" iyy="3.13e-6" iyz="0.0" izz="1.36e-5"/>
    </inertial>    
  </link>  

  <joint name="neck_to_head_fixing" type="fixed">
    <parent link="neck"/>
    <child link="head_fixing"/>
    <origin xyz="0.0 0.0 0.30"/>
  </joint>
  
  <link name="head_pan_servo_block">
    <visual>
      <geometry>
        <box size="0.057 0.032 0.066"/>        
      </geometry>
      <origin xyz="0.008 0.0 -0.008"/>      
      <material name="black"/>
    </visual>
    <collision>
      <geometry>
        <box size="0.057 0.032 0.066"/>        
      </geometry>
      <origin xyz="0.008 0.0 -0.008"/>
    </collision>
    <inertial>
      <mass value="0.015"/>
      <inertia ixx="6.73e-6" ixy="0.0" ixz="0.0" iyy="5.34e-6" iyz="0.0" izz="9.51e-6"/>
    </inertial>               
  </link>      

  <joint name="head_fixing_to_servo_block" type="fixed">
    <parent link="head_fixing"/>
    <child link="head_pan_servo_block"/>
    <origin xyz="0.0 0.0 0.047"/>
  </joint>

  <link name="head_pan_bracket">
    <visual>      
      <geometry>        
        <mesh filename="package://rodney/meshes/headPanBracket.dae"/>
      </geometry>            
    </visual>
    <collision>
      <geometry>
        <box size="0.025 0.068 0.045"/>
      </geometry>
      <origin xyz="0.0 0.0 0.0225"/>
    </collision>
    <inertial>
      <mass value="0.020"/>   
      <inertia ixx="1.11e-5" ixy="0.0" ixz="0.0" iyy="8.75e-6" iyz="0.0" izz="4.42e-6"/> 
    </inertial>           
  </link>
    
  <joint name="servo_block_to_head_pan_bracket" type="revolute">
    <axis xyz="0 0 1"/>
    <limit effort="1000.0" lower="-1.571" upper="1.571" velocity="0.5"/>
    <parent link="head_pan_servo_block"/>
    <child link="head_pan_bracket"/>
    <origin xyz="0.0 0.0 0.025"/>    
  </joint> 

  <link name="head_tilt_arm">
    <visual>      
      <geometry>        
        <mesh filename="package://rodney/meshes/headTiltArm.dae"/>
      </geometry>            
    </visual>
    <collision>
      <geometry>
        <box size="0.075 0.065 0.020"/>
      </geometry>
      <origin xyz="0.018 0.0 0.00"/> 
    </collision>
    <inertial>
      <mass value="0.020"/>   
      <inertia ixx="7.71e-6" ixy="0.0" ixz="0.0" iyy="1.64e-5" iyz="0.0" izz="1e-5"/> 
    </inertial>        
    
  </link>    

  <joint name="head_pan_bracket_to_head_tilt_arm" type="revolute">
    <axis xyz="0 1 0"/>
    <limit effort="1000.0" lower="-1.572" upper="0.3" velocity="0.5"/>
    <parent link="head_pan_bracket"/>
    <child link="head_tilt_arm"/>
    <origin xyz="0.0 -0.009 0.035"/>
  </joint>           
     
  <link name="display_bracket">
    <visual>      
      <geometry>        
        <mesh filename="package://rodney/meshes/displayBracket.dae"/>
      </geometry>
      <origin xyz="0.003 0.008 0.0"/>            
    </visual>
    <collision>
      <geometry>
        <box size="0.010 0.146 0.045"/>        
      </geometry>
      <origin xyz="-0.002 0.008 0.015"/>  
    </collision>    
    <inertial>
      <mass value="0.020"/>   
      <inertia ixx="4.82e-7" ixy="0.0" ixz="0.0" iyy="2.73e-7" iyz="0.0" izz="5.42e-7"/> 
    </inertial> 
  </link>    

  <joint name="head_tilt_arm_to_display_bracket" type="fixed">
    <parent link="head_tilt_arm"/>
    <child link="display_bracket"/>
    <origin xyz="0.056 0.0 0.0"/>
  </joint> 

  <link name="display">
    <visual>      
      <geometry>        
        <box size="0.005 0.192 0.110"/>
      </geometry>      
      <material name="black"/>           
    </visual>
    <collision>
      <geometry>
        <box size="0.005 0.192 0.110"/>        
      </geometry>        
    </collision>  
    <inertial>
      <mass value="0.010"/>   
      <!--<inertia ixx="4.08e-5" ixy="0.0" ixz="0.0" iyy="3.07e-5" iyz="0.0" izz="1.01e-5"/>-->
      <inertia ixx="1.0" ixy="0.0" ixz="0.0" iyy="1.0" iyz="0.0" izz="1.0"/>
    </inertial>    
  </link>    

  <joint name="display_bracket_to_display" type="fixed">
    <parent link="display_bracket"/>
    <child link="display"/>
    <origin xyz="0.003 0.008 0.060"/>
  </joint> 

  <!-- Gazebo stuff -->
  
  <gazebo reference="front_left_wheel">
    <material>Gazebo/Black</material>
  </gazebo>
  
  <gazebo reference="front_right_wheel">
    <material>Gazebo/Black</material>
  </gazebo>
 
  <gazebo reference="rear_left_wheel">
    <material>Gazebo/Black</material>
  </gazebo>
  
  <gazebo reference="rear_right_wheel">
    <material>Gazebo/Black</material>
  </gazebo>
  
  <gazebo>
    <plugin name="skid_steer_drive_controller" filename="libgazebo_ros_skid_steer_drive.so">
      <updateRate>100.0</updateRate>      
      <robotNamespace>/</robotNamespace>
      <leftFrontJoint>fl_brk_to_wheel</leftFrontJoint>
      <rightFrontJoint>fr_brk_to_wheel</rightFrontJoint>
      <leftRearJoint>rl_brk_to_wheel</leftRearJoint> 
      <rightRearJoint>rr_brk_to_wheel</rightRearJoint>        
      <wheelSeparation>0.180</wheelSeparation>       
      <wheelDiameter>0.106</wheelDiameter>
      <robotBaseFrame>base_link</robotBaseFrame>           
      <torque>1</torque>
      <commandTopic>cmd_vel</commandTopic>
      <broadcastTF>0</broadcastTF>     
    </plugin>    
  </gazebo>
 
</robot>
 
